Workbook

Sheet Statewide
A1: VEP Turnout Rates, including ineligible felons (VEP with the felon exclusion added back) Calculated using Highest Office Votes where Total Ballots not available (indicated in grey) | M1: Values used to calculate turnout rates Calculation: Total Ballot Count / (VEP + ineligible felons)
A2: State | B2: 2006 | C2: 2008 | D2: 2010 | E2: 2012 | F2: 2014 | G2: 2016 | H2: 2018 | I2: 2020 | J2: 2022 | K2: 2024 | M2: 2006 Total Turnout | N2: VEP incl. Ineligible Felons | O2: 2008 Total Turnout | P2: VEP incl. Ineligible Felons | Q2: 2010 Total Turnout | R2: VEP incl. Ineligible Felons | S2: 2012 Total Turnout | T2: VEP incl. Ineligible Felons | U2: 2014 Total Turnout | V2: VEP incl. Ineligible Felons | W2: 2016 Total Turnout | X2: VEP incl. Ineligible Felons | Y2: 2018 Total Turnout | Z2: VEP incl. Ineligible Felons | AA2: 2020 Total Turnout | AB2: VEP incl. Ineligible Felons | AC2: 2022 Total Turnout | AD2: VEP incl. Ineligible Felons | AE2: 2024 Total Turnout | AF2: VEP incl. Ineligible Felons
A3: Alabama | B3: =M3/N3 -> 0.36421593 | C3: =O3/P3 -> 0.59876608 | D3: =Q3/R3 -> 0.42284329 | E3: =S3/T3 -> 0.5746684 | F3: =U3/V3 -> 0.32697054 | G3: =W3/X3 -> 0.58043169 | H3: =Y3/Z3 -> 0.46353488 | I3: =AA3/AB3 -> 0.60403025 | J3: =AC3/AD3 -> 0.36935299 | K3: =AE3/AF3 -> 0.58253389 | M3: 1250401 | N3: 3433131 | O3: 2105622 | P3: 3516602 | Q3: 1503232 | R3: 3555057 | S3: 2074338 | T3: 3609626 | U3: 1191274 | V3: 3643368 | W3: 2134061 | X3: 3676679 | Y3: 1721906 | Z3: 3714728 | AA3: 2325000 | AB3: 3849145 | AC3: 1424087 | AD3: 3855626 | AE3: 2270000 | AF3: 3896769
A4: Alaska | B4: =M4/N4 -> 0.50672136 | C4: =O4/P4 -> 0.66959796 | D4: =Q4/R4 -> 0.517453 | E4: =S4/T4 -> 0.57620606 | F4: =U4/V4 -> 0.53993353 | G4: =W4/X4 -> 0.60413019 | H4: =Y4/Z4 -> 0.53495793 | I4: =AA4/AB4 -> 0.67310844 | J4: =AC4/AD4 -> 0.4974999 | K4: =AE4/AF4 -> 0.62979251 | M4: 238307 | N4: 470292 | O4: 327341 | P4: 488862 | Q4: 261128 | R4: 504641 | S4: 301694 | T4: 523587 | U4: 285431 | V4: 528641 | W4: 321271 | X4: 531791 | Y4: 285009 | Z4: 532769 | AA4: 361400 | AB4: 536912 | AC4: 267047 | AD4: 536778 | AE4: 340981 | AF4: 541418
A5: Arizona | B5: =M5/N5 -> 0.39572272 | C5: =O5/P5 -> 0.56173626 | D5: =Q5/R5 -> 0.40586483 | E5: =S5/T5 -> 0.51954552 | F5: =U5/V5 -> 0.33141311 | G5: =W5/X5 -> 0.54935478 | H5: =Y5/Z5 -> 0.47048137 | I5: =AA5/AB5 -> 0.65452952 | J5: =AC5/AD5 -> 0.48492427 | K5: =AE5/AF5 -> 0.62730097 | M5: 1553032 | N5: 3924546 | O5: 2320851 | P5: 4131567 | Q5: 1750840 | R5: 4313850 | S5: 2323579 | T5: 4472330 | U5: 1537671 | V5: 4639741 | W5: 2661497 | X5: 4844769 | Y5: 2409910 | Z5: 5122222 | AA5: 3420585 | AB5: 5226021 | AC5: 2592313 | AD5: 5345810 | AE5: 3428011 | AF5: 5464699
A6: Arkansas | B6: =M6/N6 -> 0.3788785 | C6: =O6/P6 -> 0.5189748 | D6: =Q6/R6 -> 0.37013398 | E6: =S6/T6 -> 0.49803243 | F6: =U6/V6 -> 0.39146802 | G6: =W6/X6 -> 0.51693882 | H6: =Y6/Z6 -> 0.40368629 | I6: =AA6/AB6 -> 0.54445058 | J6: =AC6/AD6 -> 0.4046982 | K6: =AE6/AF6 -> 0.52043369 | M6: 780409 | N6: 2059787 | O6: 1095958 | P6: 2111775 | Q6: 789773 | R6: 2133749 | S6: 1078548 | T6: 2165618 | U6: 852642 | V6: 2178063 | W6: 1137772 | X6: 2200980 | Y6: 898793 | Z6: 2226464 | AA6: 1223675 | AB6: 2247541 | AC6: 914227 | AD6: 2259034 | AE6: 1190172 | AF6: 2286885
A7: California | B7: =M7/N7 -> 0.41036035 | C7: =O7/P7 -> 0.61068551 | D7: =Q7/R7 -> 0.4559242 | E7: =S7/T7 -> 0.5536032 | F7: =U7/V7 -> 0.30499293 | G7: =W7/X7 -> 0.58003967 | H7: =Y7/Z7 -> 0.4873722 | I7: =AA7/AB7 -> 0.68279129 | J7: =AC7/AD7 -> 0.42814675 | K7: =AE7/AF7 -> 0.62032489 | M7: 8899059 | N7: 21685962 | O7: 13743177 | P7: 22504508 | Q7: 10529134 | R7: 23094045 | S7: 13202158 | T7: 23847691 | U7: 7513972 | V7: 24636545 | W7: 14610509 | X7: 25188810 | Y7: 12712542 | Z7: 26083847 | AA7: 17785151 | AB7: 26047712 | AC7: 11146610 | AD7: 26034555 | AE7: 16140044 | AF7: 26018695
A8: Colorado | B8: =M8/N8 -> 0.48293416 | C8: =O8/P8 -> 0.70986704 | D8: =Q8/R8 -> 0.51430141 | E8: =S8/T8 -> 0.70053994 | F8: =U8/V8 -> 0.54117428 | G8: =W8/X8 -> 0.71470269 | H8: =Y8/Z8 -> 0.61632555 | I8: =AA8/AB8 -> 0.76426291 | J8: =AC8/AD8 -> 0.58131081 | K8: =AE8/AF8 -> 0.73129254 | M8: 1586105 | N8: 3284309 | O8: 2422236 | P8: 3412239 | Q8: 1828323 | R8: 3554964 | S8: 2596173 | T8: 3705960 | U8: 2080071 | V8: 3843625 | W8: 2859216 | X8: 4000567 | Y8: 2583580 | Z8: 4191908 | AA8: 3295666 | AB8: 4312215 | AC8: 2540666 | AD8: 4370581 | AE8: 3241120 | AF8: 4432043
A9: Connecticut | B9: =M9/N9 -> 0.47031079 | C9: =O9/P9 -> 0.66024487 | D9: =Q9/R9 -> 0.45526613 | E9: =S9/T9 -> 0.60824623 | F9: =U9/V9 -> 0.42313547 | G9: =W9/X9 -> 0.64288109 | H9: =Y9/Z9 -> 0.54247651 | I9: =AA9/AB9 -> 0.69740399 | J9: =AC9/AD9 -> 0.48820372 | K9: =AE9/AF9 -> 0.66841288 | M9: 1162391 | N9: 2471538 | O9: 1646792 | P9: 2494214 | Q9: 1153872 | R9: 2534500 | S9: 1560640 | T9: 2565803 | U9: 1096556 | V9: 2591501 | W9: 1675955 | X9: 2606944 | Y9: 1421953 | Z9: 2621225 | AA9: 1861086 | AB9: 2668591 | AC9: 1297811 | AD9: 2658339 | AE9: 1788981 | AF9: 2676461
A10: Delaware | B10: =M10/N10 -> 0.41324118 | C10: =O10/P10 -> 0.64175151 | D10: =Q10/R10 -> 0.47842544 | E10: =S10/T10 -> 0.61080655 | F10: =U10/V10 -> 0.34465439 | G10: =W10/X10 -> 0.63101979 | H10: =Y10/Z10 -> 0.50384709 | I10: =AA10/AB10 -> 0.67256634 | J10: =AC10/AD10 -> 0.4220256 | K10: =AE10/AF10 -> 0.66233146 | M10: 258053 | N10: 624461 | O10: 413562 | P10: 644427 | Q10: 316754 | R10: 662076 | S10: 413921 | T10: 677663 | U10: 238110 | V10: 690866 | W10: 445228 | X10: 705569 | Y10: 365467 | Z10: 725353 | AA10: 509241 | AB10: 757161 | AC10: 325632 | AD10: 771593 | AE10: 518330 | AF10: 782584
A11: Washington DC | B11: =M11/N11 -> 0.29025608 | C11: =O11/P11 -> 0.61728826 | D11: =Q11/R11 -> 0.29471643 | E11: =S11/T11 -> 0.61358395 | F11: =U11/V11 -> 0.35487366 | G11: =W11/X11 -> 0.60358628 | H11: =Y11/Z11 -> 0.4353252 | I11: =AA11/AB11 -> 0.68868735 | J11: =AC11/AD11 -> 0.40948501 | K11: =AE11/AF11 -> 0.64941007 | M11: 122356 | N11: 421545 | O11: 266871 | P11: 432328 | Q11: 135846 | R11: 460938 | S11: 294254 | T11: 479566 | U11: 177176 | V11: 499265 | W11: 312575 | X11: 517863 | Y11: 231482 | Z11: 531745 | AA11: 346491 | AB11: 503118 | AC11: 205774 | AD11: 502519 | AE11: 328871 | AF11: 506415
A12: Florida | B12: =M12/N12 -> 0.38968201 | C12: =O12/P12 -> 0.65391509 | D12: =Q12/R12 -> 0.41457684 | E12: =S12/T12 -> 0.62285819 | F12: =U12/V12 -> 0.42357544 | G12: =W12/X12 -> 0.64745156 | H12: =Y12/Z12 -> 0.53679692 | I12: =AA12/AB12 -> 0.69887716 | J12: =AC12/AD12 -> 0.48133045 | K12: =AE12/AF12 -> 0.66515446 | M12: 4884544 | N12: 12534692 | O12: 8453743 | P12: 12927891 | Q12: 5473787 | R12: 13203311 | S12: 8538264 | T12: 13708199 | U12: 6026802 | V12: 14228403 | W12: 9580489 | X12: 14797229 | Y12: 8318824 | Z12: 15497153 | AA12: 11144855 | AB12: 15946801 | AC12: 7796916 | AD12: 16198676 | AE12: 11004209 | AF12: 16543840
A13: Georgia | B13: =M13/N13 -> 0.3404831 | C13: =O13/P13 -> 0.60181885 | D13: =Q13/R13 -> 0.39125262 | E13: =S13/T13 -> 0.56756126 | F13: =U13/V13 -> 0.36718955 | G13: =W13/X13 -> 0.57312707 | H13: =Y13/Z13 -> 0.52226233 | I13: =AA13/AB13 -> 0.64476598 | J13: =AC13/AD13 -> 0.50254497 | K13: =AE13/AF13 -> 0.65966521 | M13: 2143845 | N13: 6296480 | O13: 3940705 | P13: 6547992 | Q13: 2623035 | R13: 6704198 | S13: 3919355 | T13: 6905607 | U13: 2596947 | V13: 7072497 | W13: 4165405 | X13: 7267856 | Y13: 3949905 | Z13: 7563067 | AA13: 5023159 | AB13: 7790670 | AC13: 3964926 | AD13: 7889694 | AE13: 5297264 | AF13: 8030231
A14: Hawaii | B14: =M14/N14 -> 0.37488345 | C14: =O14/P14 -> 0.48746295 | D14: =Q14/R14 -> 0.39962014 | E14: =S14/T14 -> 0.44111225 | F14: =U14/V14 -> 0.36577083 | G14: =W14/X14 -> 0.42959914 | H14: =Y14/Z14 -> 0.38874024 | I14: =AA14/AB14 -> 0.55135451 | J14: =AC14/AD14 -> 0.4009763 | K14: =AE14/AF14 -> 0.49970385 | M14: 348988 | N14: 930924 | O14: 456064 | P14: 935587 | Q14: 386302 | R14: 966673 | S14: 437159 | T14: 991038 | U14: 369554 | V14: 1010343 | W14: 437664 | X14: 1018773 | Y14: 398657 | Z14: 1025510 | AA14: 579784 | AB14: 1051563 | AC14: 423443 | AD14: 1056030 | AE14: 522236 | AF14: 1045091
... A53: Wyoming | B53: =M53/N53 -> 0.50032 | C53: =O53/P53 -> 0.62305777 | D53: =Q53/R53 -> 0.45177267 | E53: =S53/T53 -> 0.58249186 | F53: =U53/V53 -> 0.39546705 | G53: =W53/X53 -> 0.59420599 | H53: =Y53/Z53 -> 0.4745376 | I53: =AA53/AB53 -> 0.63746126 | J53: =AC53/AD53 -> 0.44747127 | K53: =AE53/AF53 -> 0.60407017 | M53: 196217 | N53: 392183 | O53: 256035 | P53: 410933 | Q53: 190822 | R53: 422385 | S53: 250701 | T53: 430394 | U53: 171153 | V53: 432787 | W53: 258788 | X53: 435519 | Y53: 205275 | Z53: 432579 | AA53: 278503 | AB53: 436894 | AC53: 198198 | AD53: 442929 | AE53: 271123 | AF53: 448827
A54: Source | B54: https://election.lab.ufl.edu/dataset/1980-2022-general-election-turnout-rates-v1-2/ | C54: https://election.lab.ufl.edu/dataset/1980-2022-general-election-turnout-rates-v1-2/ | D54: https://election.lab.ufl.edu/dataset/1980-2022-general-election-turnout-rates-v1-2/ | E54: https://election.lab.ufl.edu/dataset/1980-2022-general-election-turnout-rates-v1-2/ | F54: https://election.lab.ufl.edu/dataset/1980-2022-general-election-turnout-rates-v1-2/ | G54: https://election.lab.ufl.edu/dataset/1980-2022-general-election-turnout-rates-v1-2/ | H54: https://election.lab.ufl.edu/dataset/1980-2022-general-election-turnout-rates-v1-2/ | I54: https://election.lab.ufl.edu/dataset/1980-2022-general-election-turnout-rates-v1-2/ | J54: https://election.lab.ufl.edu/dataset/1980-2022-general-election-turnout-rates-v1-2/ | K54: https://election.lab.ufl.edu/2024-general-election-turnout/ | M54: https://election.lab.ufl.edu/dataset/1980-2022-general-election-turnout-rates-v1-2/ | O54: https://election.lab.ufl.edu/dataset/1980-2022-general-election-turnout-rates-v1-2/ | Q54: https://election.lab.ufl.edu/dataset/1980-2022-general-election-turnout-rates-v1-2/ | S54: https://election.lab.ufl.edu/dataset/1980-2022-general-election-turnout-rates-v1-2/ | U54: https://election.lab.ufl.edu/dataset/1980-2022-general-election-turnout-rates-v1-2/ | W54: https://election.lab.ufl.edu/dataset/1980-2022-general-election-turnout-rates-v1-2/ | Y54: https://election.lab.ufl.edu/dataset/1980-2022-general-election-turnout-rates-v1-2/ | AA54: https://election.lab.ufl.edu/dataset/1980-2022-general-election-turnout-rates-v1-2/ | AC54: https://election.lab.ufl.edu/dataset/1980-2022-general-election-turnout-rates-v1-2/ | AE54: https://election.lab.ufl.edu/dataset/2024-general-election-turnout-rates-v0-4/

Sheet National
A1: Year | B1: Rate | C1: Overseas Eligible | D1: Rate incl. Overseas Eligible
A2: 2006 | B2: =SUM(Statewide!M3:M53)/SUM(Statewide!N3:N53) -> 0.41462352 | C2: 4417527 | D2: =SUM(Statewide!M3:M53)/(SUM(Statewide!N3:N53)+C2) -> 0.40592693
A3: 2008 | B3: =SUM(Statewide!O3:O53)/SUM(Statewide!P3:P53) -> 0.6264339 | C3: 4972217 | D3: =SUM(Statewide!O3:O53)/(SUM(Statewide!P3:P53)+C3) -> 0.61204609
A4: 2010 | B4: =SUM(Statewide!Q3:Q53)/SUM(Statewide!R3:R53) -> 0.42146128 | C4: 4972217 | D4: =SUM(Statewide!Q3:Q53)/(SUM(Statewide!R3:R53)+C4) -> 0.41196349
A5: 2012 | B5: =SUM(Statewide!S3:S53)/SUM(Statewide!T3:T53) -> 0.58948786 | C5: 5127418 | D5: =SUM(Statewide!S3:S53)/(SUM(Statewide!T3:T53)+C5) -> 0.57609999
A6: 2014 | B6: =SUM(Statewide!U3:U53)/SUM(Statewide!V3:V53) -> 0.3693624 | C6: 5345814 | D6: =SUM(Statewide!U3:U53)/(SUM(Statewide!V3:V53)+C6) -> 0.36079463
A7: 2016 | B7: =SUM(Statewide!W3:W53)/SUM(Statewide!X3:X53) -> 0.60459775 | C7: 4739596 | D7: =SUM(Statewide!W3:W53)/(SUM(Statewide!X3:X53)+C7) -> 0.59235363
A8: 2018 | B8: =SUM(Statewide!Y3:Y53)/SUM(Statewide!Z3:Z53) -> 0.50477073 | C8: 4971025 | D8: =SUM(Statewide!Y3:Y53)/(SUM(Statewide!Z3:Z53)+C8) -> 0.49431097
A9: 2020 | B9: =SUM(Statewide!AA3:AA53)/SUM(Statewide!AB3:AB53) -> 0.66618492 | C9: 4971025 | D9: =SUM(Statewide!AA3:AA53)/(SUM(Statewide!AB3:AB53)+C9) -> 0.65265439
A10: 2022 | B10: =SUM(Statewide!AC3:AC53)/SUM(Statewide!AD3:AD53) -> 0.46485138 | C10: 4400000 | D10: =SUM(Statewide!AC3:AC53)/(SUM(Statewide!AD3:AD53)+C10) -> 0.45651676
A11: 2024 | B11: =SUM(Statewide!AE3:AE53)/SUM(Statewide!AF3:AF53) -> 0.64480465 | C11: 3325217 | D11: =SUM(Statewide!AE3:AE53)/(SUM(Statewide!AF3:AF53)+C11) -> 0.63610455
A13: Rate = sum of state ballots / sum of state denominators (VEP + ineligible felons), same method as the VAP and VEP files.
A14: Rate incl. Overseas Eligible adds McDonald's national-only overseas-eligible estimate to the denominator, as in the VEP file.
A15: No published national rate exists for this denominator, so the VEP file's "Published National VEP Rate" column is omitted.

Sheet Felon Add-Back
A1: Year | B1: State | C1: VEP (source) | D1: Prison | E1: Probation (as reported) | F1: Parole | G1: Total Ineligible Felon (source) | H1: Felons subtracted in source VEP | I1: VEP incl. Ineligible Felons = ROUND(C+H,0) | J1: Value in Statewide sheet | K1: Check (I − J) | L1: VAP (source) | M1: % Non-citizen (source) | N1: VAP × (1 − % Non-citizen) | O1: Reconciliation gap = N − (C + H) | P1: Note
A2: 2006 | B2: Alabama | C2: 3369212 | D2: 28241 | E2: 55766 | F2: 7795 | G2: 63919 | H2: =G2 -> 63919 | I2: =ROUND(C2+H2,0) -> 3433131 | J2: =Statewide!N3 -> 3433131 | K2: =I2-J2 -> 0 | L2: 3513952 | M2: 0.023 | N2: =L2*(1-M2) -> 3433131.1 | O2: =N2-(C2+H2) -> 0.104
A3: 2006 | B3: Alaska | C3: 461202 | D3: 5069 | E3: 6095 | F3: 973 | G3: 9090 | H3: =G3 -> 9090 | I3: =ROUND(C3+H3,0) -> 470292 | J3: =Statewide!N4 -> 470292 | K3: =I3-J3 -> 0 | L3: 492452 | M3: 0.045 | N3: =L3*(1-M3) -> 470291.66 | O3: =N3-(C3+H3) -> -0.34
A4: 2006 | B4: Arizona | C4: 3845808 | D4: 35892 | E4: 73265 | F4: 6213 | G4: 78738 | H4: =G4 -> 78738 | I4: =ROUND(C4+H4,0) -> 3924546 | J4: =Statewide!N5 -> 3924546 | K4: =I4-J4 -> 0 | L4: 4490327 | M4: 0.126 | N4: =L4*(1-M4) -> 3924545.8 | O4: =N4-(C4+H4) -> -0.202
A5: 2006 | B5: Arkansas | C5: 2013638 | D5: 13729 | E5: 31508 | F5: 16666 | G5: 46149 | H5: =G5 -> 46149 | I5: =ROUND(C5+H5,0) -> 2059787 | J5: =Statewide!N6 -> 2059787 | K5: =I5-J5 -> 0 | L5: 2130080 | M5: 0.033 | N5: =L5*(1-M5) -> 2059787.4 | O5: =N5-(C5+H5) -> 0.36
A6: 2006 | B6: California | C6: 21398706 | D6: 175512 | E6: 0 | F6: 111744 | G6: 287256 | H6: =G6 -> 287256 | I6: =ROUND(C6+H6,0) -> 21685962 | J6: =Statewide!N7 -> 21685962 | K6: =I6-J6 -> 0 | L6: 26739781 | M6: 0.189 | N6: =L6*(1-M6) -> 21685962 | O6: =N6-(C6+H6) -> 0.391
A7: 2006 | B7: Colorado | C7: 3253632 | D7: 22481 | E7: 0 | F7: 8196 | G7: 30677 | H7: =G7 -> 30677 | I7: =ROUND(C7+H7,0) -> 3284309 | J7: =Statewide!N8 -> 3284309 | K7: =I7-J7 -> 0 | L7: 3569901 | M7: 0.08 | N7: =L7*(1-M7) -> 3284308.9 | O7: =N7-(C7+H7) -> -0.08
A8: 2006 | B8: Connecticut | C8: 2448401 | D8: 20566 | E8: 0 | F8: 2571 | G8: 23137 | H8: =G8 -> 23137 | I8: =ROUND(C8+H8,0) -> 2471538 | J8: =Statewide!N9 -> 2471538 | K8: =I8-J8 -> 0 | L8: 2683538 | M8: 0.079 | N8: =L8*(1-M8) -> 2471538.5 | O8: =N8-(C8+H8) -> 0.498
A9: 2006 | B9: Delaware | C9: 608176 | D9: 7206 | E9: 16958 | F9: 600 | G9: 16285 | H9: =G9 -> 16285 | I9: =ROUND(C9+H9,0) -> 624461 | J9: =Statewide!N10 -> 624461 | K9: =I9-J9 -> 0 | L9: 659410 | M9: 0.053 | N9: =L9*(1-M9) -> 624461.27 | O9: =N9-(C9+H9) -> 0.27
A10: 2006 | B10: Washington DC | C10: 421545 | D10: 0 | E10: 0 | F10: 0 | G10: 0 | H10: =G10 -> 0 | I10: =ROUND(C10+H10,0) -> 421545 | J10: =Statewide!N11 -> 421545 | K10: =I10-J10 -> 0 | L10: 466827 | M10: 0.097 | N10: =L10*(1-M10) -> 421544.78 | O10: =N10-(C10+H10) -> -0.219
A11: 2006 | B11: Florida | C11: 12300449 | D11: 92969 | E11: 272977 | F11: 4785 | G11: 234243 | H11: =G11 -> 234243 | I11: =ROUND(C11+H11,0) -> 12534692 | J11: =Statewide!N12 -> 12534692 | K11: =I11-J11 -> 0 | L11: 14211669 | M11: 0.118 | N11: =L11*(1-M11) -> 12534692 | O11: =N11-(C11+H11) -> 0.058
A12: 2006 | B12: Georgia | C12: 6009442 | D12: 52792 | E12: 422790 | F12: 22851 | G12: 287038 | H12: =G12 -> 287038 | I12: =ROUND(C12+H12,0) -> 6296480 | J12: =Statewide!N13 -> 6296480 | K12: =I12-J12 -> 0 | L12: 6799654 | M12: 0.074 | N12: =L12*(1-M12) -> 6296479.6 | O12: =N12-(C12+H12) -> -0.396
A13: 2006 | B13: Hawaii | C13: 924957 | D13: 5967 | E13: 0 | F13: 0 | G13: 5967 | H13: =G13 -> 5967 | I13: =ROUND(C13+H13,0) -> 930924 | J13: =Statewide!N14 -> 930924 | K13: =I13-J13 -> 0 | L13: 1012975 | M13: 0.081 | N13: =L13*(1-M13) -> 930924.03 | O13: =N13-(C13+H13) -> 0.025
... A52: 2006 | B52: Wyoming | C52: 386847 | D52: 2114 | E52: 5225 | F52: 609 | G52: 5336 | H52: =G52 -> 5336 | I52: =ROUND(C52+H52,0) -> 392183 | J52: =Statewide!N53 -> 392183 | K52: =I52-J52 -> 0 | L52: 400187 | M52: 0.02 | N52: =L52*(1-M52) -> 392183.26 | O52: =N52-(C52+H52) -> 0.26
A53: 2008 | B53: Alabama | C53: 3455447 | D53: 30508 | E53: 53252 | F53: 8042 | G53: 61155 | H53: =G53 -> 61155 | I53: =ROUND(C53+H53,0) -> 3516602 | J53: =Statewide!P3 -> 3516602 | K53: =I53-J53 -> 0 | L53: 3595708 | M53: 0.022 | N53: =L53*(1-M53) -> 3516602.4 | O53: =N53-(C53+H53) -> 0.424
A54: 2008 | B54: Alaska | C54: 479628 | D54: 5014 | E54: 6708 | F54: 1732 | G54: 9234 | H54: =G54 -> 9234 | I54: =ROUND(C54+H54,0) -> 488862 | J54: =Statewide!P4 -> 488862 | K54: =I54-J54 -> 0 | L54: 507645 | M54: 0.037 | N54: =L54*(1-M54) -> 488862.14 | O54: =N54-(C54+H54) -> 0.135
A55: 2008 | B55: Arizona | C55: 4047095 | D55: 39589 | E55: 82232 | F55: 7534 | G55: 84472 | H55: =G55 -> 84472 | I55: =ROUND(C55+H55,0) -> 4131567 | J55: =Statewide!P5 -> 4131567 | K55: =I55-J55 -> 0 | L55: 4673718 | M55: 0.116 | N55: =L55*(1-M55) -> 4131566.7 | O55: =N55-(C55+H55) -> -0.288
A56: 2008 | B56: Arkansas | C56: 2071520 | D56: 14716 | E56: 31169 | F56: 19908 | G56: 40255 | H56: =G56 -> 40255 | I56: =ROUND(C56+H56,0) -> 2111775 | J56: =Statewide!P6 -> 2111775 | K56: =I56-J56 -> 0 | L56: 2174846 | M56: 0.029 | N56: =L56*(1-M56) -> 2111775.5 | O56: =N56-(C56+H56) -> 0.466
A57: 2008 | B57: California | C57: 22270461 | D57: 173670 | E57: 0 | F57: 120753 | G57: 234047 | H57: =G57 -> 234047 | I57: =ROUND(C57+H57,0) -> 22504508 | J57: =Statewide!P7 -> 22504508 | K57: =I57-J57 -> 0 | L57: 27411094 | M57: 0.179 | N57: =L57*(1-M57) -> 22504508 | O57: =N57-(C57+H57) -> 0.174
A58: 2008 | B58: Colorado | C58: 3383138 | D58: 23274 | E58: 0 | F58: 11654 | G58: 29101 | H58: =G58 -> 29101 | I58: =ROUND(C58+H58,0) -> 3412239 | J58: =Statewide!P8 -> 3412239 | K58: =I58-J58 -> 0 | L58: 3708955 | M58: 0.08 | N58: =L58*(1-M58) -> 3412238.6 | O58: =N58-(C58+H58) -> -0.4
A59: 2008 | B59: Connecticut | C59: 2472389 | D59: 20661 | E59: 0 | F59: 2328 | G59: 21825 | H59: =G59 -> 21825 | I59: =ROUND(C59+H59,0) -> 2494214 | J59: =Statewide!P9 -> 2494214 | K59: =I59-J59 -> 0 | L59: 2725917 | M59: 0.085 | N59: =L59*(1-M59) -> 2494214.1 | O59: =N59-(C59+H59) -> 0.055
A60: 2008 | B60: Delaware | C60: 628468 | D60: 7075 | E60: 17216 | F60: 551 | G60: 15959 | H60: =G60 -> 15959 | I60: =ROUND(C60+H60,0) -> 644427 | J60: =Statewide!P10 -> 644427 | K60: =I60-J60 -> 0 | L60: 680493 | M60: 0.053 | N60: =L60*(1-M60) -> 644426.87 | O60: =N60-(C60+H60) -> -0.129
A61: 2008 | B61: Washington DC | C61: 432328 | D61: 0 | E61: 0 | F61: 0 | G61: 0 | H61: =G61 -> 0 | I61: =ROUND(C61+H61,0) -> 432328 | J61: =Statewide!P11 -> 432328 | K61: =I61-J61 -> 0 | L61: 481971 | M61: 0.103 | N61: =L61*(1-M61) -> 432327.99 | O61: =N61-(C61+H61) -> -0.013
A62: 2008 | B62: Florida | C62: 12683359 | D62: 102388 | E62: 279760 | F62: 4528 | G62: 244532 | H62: =G62 -> 244532 | I62: =ROUND(C62+H62,0) -> 12927891 | J62: =Statewide!P12 -> 12927891 | K62: =I62-J62 -> 0 | L62: 14558436 | M62: 0.112 | N62: =L62*(1-M62) -> 12927891 | O62: =N62-(C62+H62) -> 0.168
A63: 2008 | B63: Georgia | C63: 6285008 | D63: 52719 | E63: 397081 | F63: 23448 | G63: 262984 | H63: =G63 -> 262984 | I63: =ROUND(C63+H63,0) -> 6547992 | J63: =Statewide!P13 -> 6547992 | K63: =I63-J63 -> 0 | L63: 7063638 | M63: 0.073 | N63: =L63*(1-M63) -> 6547992.4 | O63: =N63-(C63+H63) -> 0.426
A64: 2008 | B64: Hawaii | C64: 929632 | D64: 5955 | E64: 0 | F64: 0 | G64: 5955 | H64: =G64 -> 5955 | I64: =ROUND(C64+H64,0) -> 935587 | J64: =Statewide!P14 -> 935587 | K64: =I64-J64 -> 0 | L64: 1036088 | M64: 0.097 | N64: =L64*(1-M64) -> 935587.46 | O64: =N64-(C64+H64) -> 0.464
... A103: 2008 | B103: Wyoming | C103: 405766 | D103: 2084 | E103: 5438 | F103: 727 | G103: 5167 | H103: =G103 -> 5167 | I103: =ROUND(C103+H103,0) -> 410933 | J103: =Statewide!P53 -> 410933 | K103: =I103-J103 -> 0 | L103: 418040 | M103: 0.017 | N103: =L103*(1-M103) -> 410933.32 | O103: =N103-(C103+H103) -> 0.32
A104: 2010 | B104: Alabama | C104: 3487654 | D104: 31764 | E104: 26633 | F104: 9006 | G104: 67403 | H104: =G104 -> 67403 | I104: =ROUND(C104+H104,0) -> 3555057 | J104: =Statewide!R3 -> 3555057 | K104: =I104-J104 -> 0 | L104: 3661750 | M104: 0.029 | N104: =L104*(1-M104) -> 3555559.2 | O104: =N104-(C104+H104) -> 502.25
A105: 2010 | B105: Alaska | C105: 493475 | D105: 5597 | E105: 3480 | F105: 2089 | G105: 11166 | H105: =G105 -> 11166 | I105: =ROUND(C105+H105,0) -> 504641 | J105: =Statewide!R4 -> 504641 | K105: =I105-J105 -> 0 | L105: 528459 | M105: 0.045 | N105: =L105*(1-M105) -> 504678.34 | O105: =N105-(C105+H105) -> 37.345
A106: 2010 | B106: Arizona | C106: 4225272 | D106: 40130 | E106: 40455 | F106: 7993 | G106: 88578 | H106: =G106 -> 88578 | I106: =ROUND(C106+H106,0) -> 4313850 | J106: =Statewide!R5 -> 4313850 | K106: =I106-J106 -> 0 | L106: 4806125 | M106: 0.102 | N106: =L106*(1-M106) -> 4315900.2 | O106: =N106-(C106+H106) -> 2050.25
A107: 2010 | B107: Arkansas | C107: 2082028 | D107: 16204 | E107: 14411 | F107: 21106 | G107: 51721 | H107: =G107 -> 51721 | I107: =ROUND(C107+H107,0) -> 2133749 | J107: =Statewide!R6 -> 2133749 | K107: =I107-J107 -> 0 | L107: 2216571 | M107: 0.037 | N107: =L107*(1-M107) -> 2134557.9 | O107: =N107-(C107+H107) -> 808.873
A108: 2010 | B108: California | C108: 22823850 | D108: 165062 | E108: 0 | F108: 105133 | G108: 270195 | H108: =G108 -> 270195 | I108: =ROUND(C108+H108,0) -> 23094045 | J108: =Statewide!R7 -> 23094045 | K108: =I108-J108 -> 0 | L108: 28157259 | M108: 0.18 | N108: =L108*(1-M108) -> 23088952 | O108: =N108-(C108+H108) -> -5092.62
A109: 2010 | B109: Colorado | C109: 3521135 | D109: 22815 | E109: 0 | F109: 11014 | G109: 33829 | H109: =G109 -> 33829 | I109: =ROUND(C109+H109,0) -> 3554964 | J109: =Statewide!R8 -> 3554964 | K109: =I109-J109 -> 0 | L109: 3842941 | M109: 0.075 | N109: =L109*(1-M109) -> 3554720.4 | O109: =N109-(C109+H109) -> -243.575
A110: 2010 | B110: Connecticut | C110: 2512285 | D110: 19321 | E110: 0 | F110: 2894 | G110: 22215 | H110: =G110 -> 22215 | I110: =ROUND(C110+H110,0) -> 2534500 | J110: =Statewide!R9 -> 2534500 | K110: =I110-J110 -> 0 | L110: 2771060 | M110: 0.085 | N110: =L110*(1-M110) -> 2535519.9 | O110: =N110-(C110+H110) -> 1019.9
A111: 2010 | B111: Delaware | C111: 646761 | D111: 6598 | E111: 8157 | F111: 560 | G111: 15315 | H111: =G111 -> 15315 | I111: =ROUND(C111+H111,0) -> 662076 | J111: =Statewide!R10 -> 662076 | K111: =I111-J111 -> 0 | L111: 696911 | M111: 0.05 | N111: =L111*(1-M111) -> 662065.45 | O111: =N111-(C111+H111) -> -10.55
A112: 2010 | B112: Washington DC | C112: 460938 | D112: 0 | E112: 0 | F112: 0 | G112: 0 | H112: =G112 -> 0 | I112: =ROUND(C112+H112,0) -> 460938 | J112: =Statewide!R11 -> 460938 | K112: =I112-J112 -> 0 | L112: 507942 | M112: 0.093 | N112: =L112*(1-M112) -> 460703.39 | O112: =N112-(C112+H112) -> -234.606
A113: 2010 | B113: Florida | C113: 12966802 | D113: 104306 | E113: 128110 | F113: 4093 | G113: 236509 | H113: =G113 -> 236509 | I113: =ROUND(C113+H113,0) -> 13203311 | J113: =Statewide!R12 -> 13203311 | K113: =I113-J113 -> 0 | L113: 14916715 | M113: 0.115 | N113: =L113*(1-M113) -> 13201293 | O113: =N113-(C113+H113) -> -2018.225
A114: 2010 | B114: Georgia | C114: 6394095 | D114: 56432 | E114: 228580 | F114: 25091 | G114: 310103 | H114: =G114 -> 310103 | I114: =ROUND(C114+H114,0) -> 6704198 | J114: =Statewide!R13 -> 6704198 | K114: =I114-J114 -> 0 | L114: 7253576 | M114: 0.076 | N114: =L114*(1-M114) -> 6702304.2 | O114: =N114-(C114+H114) -> -1893.776
A115: 2010 | B115: Hawaii | C115: 960761 | D115: 5912 | E115: 0 | F115: 0 | G115: 5912 | H115: =G115 -> 5912 | I115: =ROUND(C115+H115,0) -> 966673 | J115: =Statewide!R14 -> 966673 | K115: =I115-J115 -> 0 | L115: 1064539 | M115: 0.092 | N115: =L115*(1-M115) -> 966601.41 | O115: =N115-(C115+H115) -> -71.588
... A154: 2010 | B154: Wyoming | C154: 416931 | D154: 2112 | E154: 2660 | F154: 682 | G154: 5454 | H154: =G154 -> 5454 | I154: =ROUND(C154+H154,0) -> 422385 | J154: =Statewide!R53 -> 422385 | K154: =I154-J154 -> 0 | L154: 429977 | M154: 0.018 | N154: =L154*(1-M154) -> 422237.41 | O154: =N154-(C154+H154) -> -147.586
...

Sheet Sources & Notes
A1: Year | B1: Source page | C1: Data file | D1: Citation
A2: 2006 | B2: https://election.lab.ufl.edu/dataset/1980-2022-general-election-turnout-rates-v1-2/ | C2: https://election.lab.ufl.edu/data-downloads/turnoutdata/Turnout_1980_2022_v1.2.csv | D2: McDonald, Michael P. 2024. "1980-2022 General Election Turnout Rates (v1.2)." University of Florida Election Lab (released Oct. 8, 2024). Accessed Sept. 27, 2026.
A3: 2008 | B3: https://election.lab.ufl.edu/dataset/1980-2022-general-election-turnout-rates-v1-2/ | C3: https://election.lab.ufl.edu/data-downloads/turnoutdata/Turnout_1980_2022_v1.2.csv | D3: McDonald, Michael P. 2024. "1980-2022 General Election Turnout Rates (v1.2)." University of Florida Election Lab (released Oct. 8, 2024). Accessed Sept. 27, 2026.
A4: 2010 | B4: https://election.lab.ufl.edu/dataset/1980-2022-general-election-turnout-rates-v1-2/ | C4: https://election.lab.ufl.edu/data-downloads/turnoutdata/Turnout_1980_2022_v1.2.csv | D4: McDonald, Michael P. 2024. "1980-2022 General Election Turnout Rates (v1.2)." University of Florida Election Lab (released Oct. 8, 2024). Accessed Sept. 27, 2026.
A5: 2012 | B5: https://election.lab.ufl.edu/dataset/1980-2022-general-election-turnout-rates-v1-2/ | C5: https://election.lab.ufl.edu/data-downloads/turnoutdata/Turnout_1980_2022_v1.2.csv | D5: McDonald, Michael P. 2024. "1980-2022 General Election Turnout Rates (v1.2)." University of Florida Election Lab (released Oct. 8, 2024). Accessed Sept. 27, 2026.
A6: 2014 | B6: https://election.lab.ufl.edu/dataset/1980-2022-general-election-turnout-rates-v1-2/ | C6: https://election.lab.ufl.edu/data-downloads/turnoutdata/Turnout_1980_2022_v1.2.csv | D6: McDonald, Michael P. 2024. "1980-2022 General Election Turnout Rates (v1.2)." University of Florida Election Lab (released Oct. 8, 2024). Accessed Sept. 27, 2026.
A7: 2016 | B7: https://election.lab.ufl.edu/dataset/1980-2022-general-election-turnout-rates-v1-2/ | C7: https://election.lab.ufl.edu/data-downloads/turnoutdata/Turnout_1980_2022_v1.2.csv | D7: McDonald, Michael P. 2024. "1980-2022 General Election Turnout Rates (v1.2)." University of Florida Election Lab (released Oct. 8, 2024). Accessed Sept. 27, 2026.
A8: 2018 | B8: https://election.lab.ufl.edu/dataset/1980-2022-general-election-turnout-rates-v1-2/ | C8: https://election.lab.ufl.edu/data-downloads/turnoutdata/Turnout_1980_2022_v1.2.csv | D8: McDonald, Michael P. 2024. "1980-2022 General Election Turnout Rates (v1.2)." University of Florida Election Lab (released Oct. 8, 2024). Accessed Sept. 27, 2026.
A9: 2020 | B9: https://election.lab.ufl.edu/dataset/1980-2022-general-election-turnout-rates-v1-2/ | C9: https://election.lab.ufl.edu/data-downloads/turnoutdata/Turnout_1980_2022_v1.2.csv | D9: McDonald, Michael P. 2024. "1980-2022 General Election Turnout Rates (v1.2)." University of Florida Election Lab (released Oct. 8, 2024). Accessed Sept. 27, 2026.
A10: 2022 | B10: https://election.lab.ufl.edu/dataset/1980-2022-general-election-turnout-rates-v1-2/ | C10: https://election.lab.ufl.edu/data-downloads/turnoutdata/Turnout_1980_2022_v1.2.csv | D10: McDonald, Michael P. 2024. "1980-2022 General Election Turnout Rates (v1.2)." University of Florida Election Lab (released Oct. 8, 2024). Accessed Sept. 27, 2026.
A11: 2024 | B11: https://election.lab.ufl.edu/2024-general-election-turnout/ | C11: https://election.lab.ufl.edu/data-downloads/turnoutdata/Turnout_2024G_v0.4.csv | D11: McDonald, Michael P. University of Florida Election Lab, "Turnout Rates in the 2024 General Election," v0.4 (released March 2, 2026). Accessed Sept. 27, 2026.
A13: Notes
A14: Denominator: VEP incl. ineligible felons = McDonald's state VEP + his "Total Ineligible Felon" count (prison + parole + felony probationers, in states whose law disenfranchises them). This undoes the felon exclusion and leaves the rest of his VEP (VAP, non-citizen adjustment) as published. State denominators exclude overseas eligible voters, as in the VEP file. The "Felon Add-Back" sheet shows every input and formula; its Check column is 0 for all 510 state-years.
A15: What this is not: it is not a count of everyone with a felony record, and it does not add back people disenfranchised after completing a sentence. McDonald never subtracts those, so they are already inside his VEP. Conceptually the result is McDonald's citizen voting-age population estimate.
A16: Source change (Sept. 27, 2026): 2006–2022 denominators now come from McDonald's UF Election Lab time series v1.2 (Oct. 8, 2024), his latest revision, replacing the per-year electproject.org sheets used before (previous version: git commit 650719c). 2024 is unchanged (UF 2024 v0.4, the latest 2024 release).
A17: Numerators are unchanged. For all 459 state-years 2006–2022 they equal v1.2's TOTAL_BALLOTS_COUNTED, or VOTE_FOR_HIGHEST_OFFICE where total ballots are not reported (grey), exactly as in the per-year sheets.
A18: v1.2 revises VAP for 2010–2022 (Census vintage updates; 2006 and 2008 unchanged) and VEP for every year. It also fixes the per-year sheets' internal inconsistencies (2006, 2014; 2022 MD, WI, FL, ME, VT): in v1.2, VAP×(1−%non-citizen)−felons = VEP within rounding for every state-year except 2010 (47 states) and 2020 (44 states), where the gap is at most 0.06% of VEP and does not match any felon component.
A19: v1.2 is published as whole numbers with %non-citizen to two decimals (0.01 pt); values here are as published.
A20: Add-back rule under v1.2: the full felon total is added back for every state-year. The previous version (per-year sheets) had to special-case 2022 MD and WI, whose published VEP had not subtracted all listed felons; v1.2 subtracts them, so no exceptions are needed. In the 91 state-years (2010, 2020) where v1.2 does not reconcile, the gap (column O) is at most 0.06% of VEP and matches no felon component, so it is not a felon-subtraction difference.
A21: Probation: the "Probation" column is as reported; for most years it is total probation and the total counts only the felony share. Column G (the source total) is what is added back.
A22: 2024 (UF v0.4): VEP + felons, both as published (whole numbers).
